<?xml version="1.0"?>
<robot xmlns:xacro="http://www.ros.org/wiki/xacro" >

    <xacro:include filename="inertial_macros.xacro"/>

    <material name="white">
        <color rgba="1 1 1 1" />
    </material>

    <material name="orange">
        <color rgba="1 0.3 0.1 1"/>
    </material>

    <material name="blue">
        <color rgba="0.2 0.2 1 1"/>
    </material>

    <material name="black">
        <color rgba="0 0 0 1"/>
    </material>

    <material name="red">
        <color rgba="1 0 0 1"/>
    </material>

    <!-- BASE LINK -->

    <link name="base_link">

    </link>


    <!-- CHASSIS LINK -->

    <joint name="chassis_joint" type="fixed">
        <parent link="base_link"/>
        <child link="chassis"/>
        <origin xyz="-0.1 0 0"/>
    </joint>

    <link name="chassis">
        <visual>
            <origin xyz="0.15 0 0.075"/>
            <geometry>
                <box size="0.3 0.3 0.15"/>
            </geometry>
            <material name="white"/>
        </visual>
        <collision>
            <origin xyz="0.15 0 0.075"/>
            <geometry>
                <box size="0.3 0.3 0.15"/>
            </geometry>
        </collision>
        <xacro:inertial_box mass="0.5" x="0.3" y="0.3" z="0.15">
            <origin xyz="0.15 0 0.075" rpy="0 0 0"/>
        </xacro:inertial_box>
    </link>

    <gazebo reference="chassis">
        <material>Gazebo/White</material>
    </gazebo>

    <!-- LEFT WHEEL LINK -->

    <joint name="left_wheel_joint" type="continuous">
        <parent link="base_link"/>
        <child link="left_wheel"/>
        <origin xyz="0 0.175 0" rpy="-${pi/2} 0 0" />
        <axis xyz="0 0 1"/>
    </joint>

    <link name="left_wheel">
        <visual>
            <geometry>
                <cylinder radius="0.05" length="0.04"/>
            </geometry>
            <material name="blue"/>
        </visual>
        <collision>
            <geometry>
                <cylinder radius="0.05" length="0.04"/>
            </geometry>
        </collision>
        <xacro:inertial_cylinder mass="0.1" length="0.04" radius="0.05">
            <origin xyz="0 0 0" rpy="0 0 0"/>
        </xacro:inertial_cylinder>
    </link>

    <gazebo reference="left_wheel">
        <material>Gazebo/Blue</material>
    </gazebo>




    <!-- RIGHT WHEEL LINK -->

    <joint name="right_wheel_joint" type="continuous">
        <parent link="base_link"/>
        <child link="right_wheel"/>
        <origin xyz="0 -0.175 0" rpy="${pi/2} 0 0" />
        <axis xyz="0 0 -1"/>
    </joint>

    <link name="right_wheel">
        <visual>
            <geometry>
                <cylinder radius="0.05" length="0.04"/>
            </geometry>
            <material name="blue"/>
        </visual>
        <collision>
            <geometry>
                <cylinder radius="0.05" length="0.04"/>
            </geometry>
        </collision>
        <xacro:inertial_cylinder mass="0.1" length="0.04" radius="0.05">
            <origin xyz="0 0 0" rpy="0 0 0"/>
        </xacro:inertial_cylinder>
    </link>

    <gazebo reference="right_wheel">
        <material>Gazebo/Blue</material>
    </gazebo>


    <!-- CASTER WHEEL LINK -->

    <joint name="caster_wheel_joint" type="fixed">
        <parent link="chassis"/>
        <child link="caster_wheel"/>
        <origin xyz="0.24 0 0"/>
    </joint>


    <link name="caster_wheel">
        <visual>
            <geometry>
                <sphere radius="0.05"/>
            </geometry>
            <material name="black"/>
        </visual>
        <collision>
            <geometry>
                <sphere radius="0.05"/>
            </geometry>
        </collision>
        <xacro:inertial_sphere mass="0.1" radius="0.05">
            <origin xyz="0 0 0" rpy="0 0 0"/>
        </xacro:inertial_sphere>
    </link>

    <gazebo reference="caster_wheel">
        <material>Gazebo/Black</material>
        <mu1 value="0.001"/>
        <mu2 value="0.001"/>
    </gazebo>


    <!-- IMU sensor -->
<gazebo>
  <sensor name="imu_sensor" type="imu">
    <always_on>true</always_on>
    <update_rate>50</update_rate>

    <imu>
      <noise>
        <type>gaussian</type>
        <rate>
          <mean>0.0</mean>
          <stddev>0.001</stddev>
        </rate>
        <accel>
          <mean>0.0</mean>
          <stddev>0.1</stddev>
        </accel>
      </noise>
    </imu>

    <plugin name="imu_plugin" filename="libgazebo_ros_imu_sensor.so">
      <ros>
        <namespace>/</namespace>
        <remapping>~/out:=/imu</remapping>
      </ros>
      <frame_name>imu_link</frame_name>
    </plugin>
  </sensor>
</gazebo>

<!-- IMU START -->
<link name="imu_link"/>

<joint IMUname="imu_joint" type="fixed">
  <parent link="base_link"/>
  <child link="imu_link"/>
  <origin xyz="0 0 0.1" rpy="0 0 0"/>
</joint>

<gazebo reference="imu_link">
  <sensor name="imu_sensor" type="imu">

    <update_rate>50</update_rate>
    <always_on>true</always_on>

    <plugin name="imu_plugin" filename="libgazebo_ros_imu_sensor.so">
      <ros>
        <namespace>/</namespace>
      </ros>

      <frame_name>imu_link</frame_name>
      <topic_name>/imu</topic_name>
    </plugin>

  </sensor>
</gazebo>
<!-- IMU END -->

<link name="imu_link">
</link>

<joint name="imu_joint" type="fixed">
  <parent link="base_link"/>
  <child link="imu_link"/>
  <origin xyz="0 0 0.1" rpy="0 0 0"/>
</joint>

</robot>